Workbook

Sheet Proyecto
C2: ETIQUETADO DE SALIDAS Y ELEVACIÓN DE RACKS DE TELECOMUNICACIONES
C3: Version: 1.5
C5: DATOS DEL PROYECTO | E5: / Project data
C6: Nombre del proyecto
C7: Proyecto #
C8: Ubicación
C9: Fecha
C10: Elaboró
C11: Revisión del plano
C12: Jack por defecto | D12: Jack Cat 6A UTP azul (Mini-Com TX6A)
C14: NOMENCLATURA DE TIPOS DE SALIDA | E14: / Outlet types
C15: Código | D15: Tipo de salida
C16: D | D16: Datos
C17: V | D17: Voz
C18: C | D18: CCTV
C19: B | D19: BMS
C20: W | D20: Access point (WAP)
C21: T | D21: TV
C22: A | D22: Control de acceso
C23: S | D23: Audio / video IP
C24: G | D24: Gateways
C25: R | D25: GRMS
C27: - | D27: Puerto sin salida (anula el tipo del panel)
C29: INSTRUCCIONES
C30: 1. Llene los datos del proyecto y la nomenclatura de tipos de salida (aplican a todos los cuartos).
C31: 2. Cada cuarto de telecomunicaciones va en su propia pestaña (TR-01, TR-02…), ubicada entre INICIO_TR y FIN_TR.
C32: 3. Para agregar un cuarto: Ctrl + arrastrar la pestaña TR-01 (vacía) o una MUESTRA (piso, gabinete o pared) hasta quedar entre INICIO_TR y FIN_TR, y cambiarle el nombre.
C33: 4. En cada cuarto: elija el rack, los organizadores verticales y los equipos de arriba hacia abajo; la vista del rack y el etiquetado se generan solos.
C34: 5. En la lista de equipos, asigne a cada patch panel su tipo de salida (D, C, W…) y cuántas salidas usa; el etiquetado se llena solo y se puede ajustar puerto por puerto.
C35: 6. La pestaña Catalogo se puede ampliar con más equipos (filas libres al final).
C36: 7. La pestaña Resumen consolida cuartos, salidas por tipo y lista de materiales.
C38: Formato de etiqueta: [Cuarto]-[Panel]-[Puerto], ej. 1A-AA-01. La etiqueta en la salida del puesto de trabajo es la misma que en el puerto del rack.
C40: MARCAS DE REFERENCIA POR SISTEMA | E40: / Reference brands
C41: Sistema | D41: Marca
C42: Pasivo / racks | D42: Panduit (racks R2P, gabinetes FlexFusion, racks y gabinetes de pared WBH / PanZone, patch panels, jacks Mini-Com, organizadores, fibra Opticom)
C43: Switches | D43: Cisco Catalyst 9200L
C44: CCTV | D44: Axis (grabadores AXIS Camera Station S12)
C45: Control de acceso | D45: Kantech (KT-400) o Software House (iSTAR Ultra); fuentes Altronix Maximal R
C46: Audio | D46: Crown (amplificadores), BSS Soundweb (DSP), TOA VM-2000 (evacuación), Bose FreeSpace (parlantes), AMX SVSI (AV/IP)

Sheet Servicios y fibra
B2: SERVICIOS, REDES LAN, CUARTOS Y FIBRA TRONCAL
B3: Celdas en verde claro = datos a llenar. Las salidas requeridas se comparan contra las salidas etiquetadas en las pestañas de cada cuarto (Resumen). La fibra es un estimado: valide por el ingeniero.
B5: PARÁMETROS
B6: Reserva de puertos | C6: 0.3
B7: Reserva de fibra | C7: 0.2
B8: ¿Enlaces de fibra redundantes? | C8: No
B9: Distancia límite fibra multimodo (m) | C9: 300
B10: ¿Todos los servicios comparten una misma red LAN? | C10: Sí
B11: Cantidad de redes LAN disponibles | C11: 1
B12: Redes LAN en uso (servicios activos) | C12: =SUMPRODUCT(--(COUNTIFS($D$15:$D$24,"Sí",$G$15:$G$24,{1,2,3,4})>0)) -> 1
B13: SERVICIOS
B14: Código | C14: Servicio | D14: Activo | E14: PoE | F14: Red LAN (1-4) | G14: Red LAN efectiva
B15: =Proyecto!C16 -> D | C15: =Proyecto!D16 -> Datos | D15: Sí | E15: No | F15: 1 | G15: =IF(OR($C$10="Sí",F15>$C$11),1,F15) -> 1
B16: =Proyecto!C17 -> V | C16: =Proyecto!D17 -> Voz | D16: Sí | E16: No | F16: 1 | G16: =IF(OR($C$10="Sí",F16>$C$11),1,F16) -> 1
B17: =Proyecto!C18 -> C | C17: =Proyecto!D18 -> CCTV | D17: Sí | E17: Sí | F17: 1 | G17: =IF(OR($C$10="Sí",F17>$C$11),1,F17) -> 1
B18: =Proyecto!C19 -> B | C18: =Proyecto!D19 -> BMS | D18: Sí | E18: Sí | F18: 1 | G18: =IF(OR($C$10="Sí",F18>$C$11),1,F18) -> 1
B19: =Proyecto!C20 -> W | C19: =Proyecto!D20 -> Access point (WAP) | D19: Sí | E19: Sí | F19: 1 | G19: =IF(OR($C$10="Sí",F19>$C$11),1,F19) -> 1
B20: =Proyecto!C21 -> T | C20: =Proyecto!D21 -> TV | D20: No | E20: No | F20: 1 | G20: =IF(OR($C$10="Sí",F20>$C$11),1,F20) -> 1
B21: =Proyecto!C22 -> A | C21: =Proyecto!D22 -> Control de acceso | D21: Sí | E21: Sí | F21: 1 | G21: =IF(OR($C$10="Sí",F21>$C$11),1,F21) -> 1
B22: =Proyecto!C23 -> S | C22: =Proyecto!D23 -> Audio / video IP | D22: No | E22: No | F22: 1 | G22: =IF(OR($C$10="Sí",F22>$C$11),1,F22) -> 1
B23: =Proyecto!C24 -> G | C23: =Proyecto!D24 -> Gateways | D23: No | E23: Sí | F23: 1 | G23: =IF(OR($C$10="Sí",F23>$C$11),1,F23) -> 1
B24: =Proyecto!C25 -> R | C24: =Proyecto!D25 -> GRMS | D24: No | E24: Sí | F24: 1 | G24: =IF(OR($C$10="Sí",F24>$C$11),1,F24) -> 1
B27: CUARTOS DE TELECOMUNICACIONES
B28: Código | C28: Nombre | D28: Tipo | E28: Distancia al principal (m)
B39: SALIDAS REQUERIDAS POR SERVICIO Y CUARTO (en los puestos de trabajo)
B40: Código | C40: Servicio | D40: =IF($B$29="","",$B$29) | E40: =IF($B$30="","",$B$30) | F40: =IF($B$31="","",$B$31) | G40: =IF($B$32="","",$B$32) | H40: =IF($B$33="","",$B$33) | I40: =IF($B$34="","",$B$34) | J40: =IF($B$35="","",$B$35) | K40: =IF($B$36="","",$B$36) | L40: Total | M40: Con reserva
B41: =B15 -> D | C41: =C15 -> Datos | L41: =SUM(D41:K41) -> 0 | M41: =ROUNDUP(L41*(1+$C$6),0) -> 0
B42: =B16 -> V | C42: =C16 -> Voz | L42: =SUM(D42:K42) -> 0 | M42: =ROUNDUP(L42*(1+$C$6),0) -> 0
B43: =B17 -> C | C43: =C17 -> CCTV | L43: =SUM(D43:K43) -> 0 | M43: =ROUNDUP(L43*(1+$C$6),0) -> 0
B44: =B18 -> B | C44: =C18 -> BMS | L44: =SUM(D44:K44) -> 0 | M44: =ROUNDUP(L44*(1+$C$6),0) -> 0
B45: =B19 -> W | C45: =C19 -> Access point (WAP) | L45: =SUM(D45:K45) -> 0 | M45: =ROUNDUP(L45*(1+$C$6),0) -> 0
B46: =B20 -> T | C46: =C20 -> TV | L46: =SUM(D46:K46) -> 0 | M46: =ROUNDUP(L46*(1+$C$6),0) -> 0
B47: =B21 -> A | C47: =C21 -> Control de acceso | L47: =SUM(D47:K47) -> 0 | M47: =ROUNDUP(L47*(1+$C$6),0) -> 0
B48: =B22 -> S | C48: =C22 -> Audio / video IP | L48: =SUM(D48:K48) -> 0 | M48: =ROUNDUP(L48*(1+$C$6),0) -> 0
B49: =B23 -> G | C49: =C23 -> Gateways | L49: =SUM(D49:K49) -> 0 | M49: =ROUNDUP(L49*(1+$C$6),0) -> 0
B50: =B24 -> R | C50: =C24 -> GRMS | L50: =SUM(D50:K50) -> 0 | M50: =ROUNDUP(L50*(1+$C$6),0) -> 0
B51: TOTAL | D51: =SUM(D41:D50) -> 0 | E51: =SUM(E41:E50) -> 0 | F51: =SUM(F41:F50) -> 0 | G51: =SUM(G41:G50) -> 0 | H51: =SUM(H41:H50) -> 0 | I51: =SUM(I41:I50) -> 0 | J51: =SUM(J41:J50) -> 0 | K51: =SUM(K41:K50) -> 0 | ... M51: =SUM(M41:M50) -> 0
B54: COBERTURA: SALIDAS REQUERIDAS (CON RESERVA) CONTRA SALIDAS ETIQUETADAS EN LOS RACKS
B55: Código | C55: Servicio | D55: Requeridas c/reserva | E55: Etiquetadas en racks | F55: Diferencia | G55: Estado
B56: =B41 -> D | C56: =C41 -> Datos | D56: =M41 -> 0 | E56: =SUMIF(Resumen!$AA$16:$AA$27,B56,Resumen!$AC$16:$AC$27) -> 0 | F56: =E56-D56 -> 0 | G56: =IF(D56=0,"",IF(F56>=0,"✓ Cubierto","⚠ Faltan "&-F56&" puertos"))
...

Sheet Resumen
C2: RESUMEN — ETIQUETADO Y RACKS DE TELECOMUNICACIONES
C4: DATOS DEL PROYECTO | F4: / Project data
C5: Nombre del proyecto | D5: =Proyecto!D6&""
C6: Proyecto # | D6: =Proyecto!D7&"" | AE6: =Catalogo!$B6&"" -> Rack | AF6: =Catalogo!$C6&"" -> Rack 2 postes 45RU aluminio, canal 3", rosca #12-24 | AG6: =Catalogo!$D6&"" -> Panduit | AH6: =Catalogo!$E6&"" -> R2P | AI6: =SUM(INICIO_TR:FIN_TR!$BA$6) -> 1
C7: Ubicación | D7: =Proyecto!D8&"" | AE7: =Catalogo!$B7&"" -> Rack | AF7: =Catalogo!$C7&"" -> Rack 2 postes 45RU acero, canal 3" | AG7: =Catalogo!$D7&"" -> Panduit | AH7: =Catalogo!$E7&"" -> R2PS | AI7: =SUM(INICIO_TR:FIN_TR!$BA$7) -> 0
C8: Fecha | D8: =Proyecto!D9&"" | AE8: =Catalogo!$B8&"" -> Rack | AF8: =Catalogo!$C8&"" -> Rack 2 postes 45RU acero, canal 6" | AG8: =Catalogo!$D8&"" -> Panduit | AH8: =Catalogo!$E8&"" -> R2P6S | AI8: =SUM(INICIO_TR:FIN_TR!$BA$8) -> 0
C9: Elaboró | D9: =Proyecto!D10&"" | AE9: =Catalogo!$B9&"" -> Rack | AF9: =Catalogo!$C9&"" -> Rack 2 postes 42RU aluminio, canal 3" | AG9: =Catalogo!$D9&"" -> Panduit | AH9: =Catalogo!$E9&"" -> R2P79 | AI9: =SUM(INICIO_TR:FIN_TR!$BA$9) -> 0
AE10: =Catalogo!$B10&"" -> Organizador vertical | AF10: =Catalogo!$C10&"" -> Org. vertical 6" frontal (PatchRunner 2) | AG10: =Catalogo!$D10&"" -> Panduit | AH10: =Catalogo!$E10&"" -> PR2VFD06 | AI10: =SUM(INICIO_TR:FIN_TR!$BA$10) -> 0
C11: Cuartos detectados | D11: =_xlfn.SHEETS(INICIO_TR:FIN_TR!$A$1)-2 -> 1 | AE11: =Catalogo!$B11&"" -> Organizador vertical | AF11: =Catalogo!$C11&"" -> Org. vertical 8" frontal (PatchRunner 2) | AG11: =Catalogo!$D11&"" -> Panduit | AH11: =Catalogo!$E11&"" -> PR2VFD08 | AI11: =SUM(INICIO_TR:FIN_TR!$BA$11) -> 0
AE12: =Catalogo!$B12&"" -> Organizador vertical | AF12: =Catalogo!$C12&"" -> Org. vertical 10" frontal (PatchRunner 2) | AG12: =Catalogo!$D12&"" -> Panduit | AH12: =Catalogo!$E12&"" -> PR2VFD10 | AI12: =SUM(INICIO_TR:FIN_TR!$BA$12) -> 0
C13: {=_xlfn.LET(_xlpm.d,_xlfn.VSTACK(INICIO_TR:FIN_TR!$AS$3:$BA$3),_xlpm.f,_xlfn._xlws.FILTER(_xlpm.d,ISTEXT(_xlfn.CHOOSECOLS(_xlpm.d,1))),_xlpm.tot,_xlfn.HSTACK("TOTAL","",SUM(_xlfn.CHOOSECOLS(_xlpm.f,3)),SUM(_xlfn.CHOOSECOLS(_xlpm.f,4)),IFERROR(TEXT(SUM(_xlfn.CHOOSECOLS(_xlpm.f,3))/(SUM(_xlfn.CHOOSECOLS(_xlpm.f,3))+SUM(_xlfn.CHOOSECOLS(_xlpm.f,4))),"0%"),"-"),SUM(_xlfn.CHOOSECOLS(_xlpm.f,6)),SUM(_xlfn.CHOOSECOLS(_xlpm.f,7)),SUM(_xlfn.CHOOSECOLS(_xlpm.f,8)),IFERROR(TEXT(SUM(_xlfn.CHOOSECOLS(_xlpm.f,8))/SUM(_xlfn.CHOOSECOLS(_xlpm.f,7)),"0%"),"-")),_xlpm.c,AA16:AC27,_xlpm.b,AE6:AI125,IFERROR(_xlfn.VSTACK({"CUARTOS DE TELECOMUNICACIONES"},{"Cuarto","Descripción","RU ocupados","RU libres","% llenado rack","Patch panels","Puertos","Salidas","% llenado PP"},_xlpm.f,_xlpm.tot,{""},{"SALIDAS POR TIPO"},{"Código","Tipo de salida","Cantidad"},_xlfn._xlws.FILTER(_xlpm.c,(_xlfn.CHOOSECOLS(_xlpm.c,1)<>"")*(_xlfn.CHOOSECOLS(_xlpm.c,3)>0),"Sin salidas asignadas"),{""},{"LISTA DE MATERIALES"},{"Categoría","Descripción","Marca","Número de parte","Cantidad"},_xlfn._xlws.FILTER(_xlpm.b,_xlfn.CHOOSECOLS(_xlpm.b,5)>0,"Sin materiales")),""))} -> CUARTOS DE TELECOMUNICACIONES | AE13: =Catalogo!$B13&"" -> Organizador vertical | AF13: =Catalogo!$C13&"" -> Org. vertical 12" frontal (PatchRunner 2) | AG13: =Catalogo!$D13&"" -> Panduit | AH13: =Catalogo!$E13&"" -> PR2VFD12 | AI13: =SUM(INICIO_TR:FIN_TR!$BA$13) -> 0
C14: Cuarto | D14: Descripción | E14: RU ocupados | F14: RU libres | G14: % llenado rack | H14: Patch panels | I14: Puertos | J14: Salidas | K14: % llenado PP | AE14: =Catalogo!$B14&"" -> Organizador vertical | AF14: =Catalogo!$C14&"" -> Org. vertical 6" frontal/posterior (PatchRunner 2) | AG14: =Catalogo!$D14&"" -> Panduit | AH14: =Catalogo!$E14&"" -> PR2VD06 | AI14: =SUM(INICIO_TR:FIN_TR!$BA$14) -> 2
E15: 2 | F15: 43 | G15: 4% | H15: 1 | I15: 48 | J15: 2 | K15: 4% | AE15: =Catalogo!$B15&"" -> Organizador vertical | AF15: =Catalogo!$C15&"" -> Org. vertical 8" frontal/posterior (PatchRunner 2) | AG15: =Catalogo!$D15&"" -> Panduit | AH15: =Catalogo!$E15&"" -> PR2VD08 | AI15: =SUM(INICIO_TR:FIN_TR!$BA$15) -> 0
C16: TOTAL | E16: 2 | F16: 43 | G16: 4% | H16: 1 | I16: 48 | J16: 2 | K16: 4% | AA16: =Proyecto!$C16&"" -> D | AB16: =Proyecto!$D16&"" -> Datos | AC16: =SUM(INICIO_TR:FIN_TR!$AQ$16) -> 0 | AE16: =Catalogo!$B16&"" -> Organizador vertical | AF16: =Catalogo!$C16&"" -> Org. vertical 10" frontal/posterior (PatchRunner 2) | AG16: =Catalogo!$D16&"" -> Panduit | AH16: =Catalogo!$E16&"" -> PR2VD10 | AI16: =SUM(INICIO_TR:FIN_TR!$BA$16) -> 0
AA17: =Proyecto!$C17&"" -> V | AB17: =Proyecto!$D17&"" -> Voz | AC17: =SUM(INICIO_TR:FIN_TR!$AQ$17) -> 0 | AE17: =Catalogo!$B17&"" -> Organizador vertical | AF17: =Catalogo!$C17&"" -> Org. vertical 12" frontal/posterior (PatchRunner 2) | AG17: =Catalogo!$D17&"" -> Panduit | AH17: =Catalogo!$E17&"" -> PR2VD12 | AI17: =SUM(INICIO_TR:FIN_TR!$BA$17) -> 0
C18: SALIDAS POR TIPO | AA18: =Proyecto!$C18&"" -> C | AB18: =Proyecto!$D18&"" -> CCTV | AC18: =SUM(INICIO_TR:FIN_TR!$AQ$18) -> 1 | AE18: =Catalogo!$B18&"" -> Organizador vertical | AF18: =Catalogo!$C18&"" -> Org. vertical 4.9" frontal/posterior (NetRunner) | AG18: =Catalogo!$D18&"" -> Panduit | AH18: =Catalogo!$E18&"" -> WMPV45E | AI18: =SUM(INICIO_TR:FIN_TR!$BA$18) -> 0
C19: Código | D19: Tipo de salida | E19: Cantidad | AA19: =Proyecto!$C19&"" -> B | AB19: =Proyecto!$D19&"" -> BMS | AC19: =SUM(INICIO_TR:FIN_TR!$AQ$19) -> 0 | AE19: =Catalogo!$B19&"" -> Organizador vertical | AF19: =Catalogo!$C19&"" -> Org. vertical 6.7" frontal/posterior (NetRunner) | AG19: =Catalogo!$D19&"" -> Panduit | AH19: =Catalogo!$E19&"" -> WMPVHC45E | AI19: =SUM(INICIO_TR:FIN_TR!$BA$19) -> 0
C20: C | D20: CCTV | E20: 1 | AA20: =Proyecto!$C20&"" -> W | AB20: =Proyecto!$D20&"" -> Access point (WAP) | AC20: =SUM(INICIO_TR:FIN_TR!$AQ$20) -> 1 | AE20: =Catalogo!$B20&"" -> Patch panel cobre | AF20: =Catalogo!$C20&"" -> Patch panel plano 24 puertos 1RU | AG20: =Catalogo!$D20&"" -> Panduit | AH20: =Catalogo!$E20&"" -> CPP24FMWBLY | AI20: =SUM(INICIO_TR:FIN_TR!$BA$20) -> 0
C21: W | D21: Access point (WAP) | E21: 1 | AA21: =Proyecto!$C21&"" -> T | AB21: =Proyecto!$D21&"" -> TV | AC21: =SUM(INICIO_TR:FIN_TR!$AQ$21) -> 0 | AE21: =Catalogo!$B21&"" -> Patch panel cobre | AF21: =Catalogo!$C21&"" -> Patch panel plano 48 puertos 2RU | AG21: =Catalogo!$D21&"" -> Panduit | AH21: =Catalogo!$E21&"" -> CPP48FMWBLY | AI21: =SUM(INICIO_TR:FIN_TR!$BA$21) -> 1
AA22: =Proyecto!$C22&"" -> A | AB22: =Proyecto!$D22&"" -> Control de acceso | AC22: =SUM(INICIO_TR:FIN_TR!$AQ$22) -> 0 | AE22: =Catalogo!$B22&"" -> Patch panel cobre | AF22: =Catalogo!$C22&"" -> Patch panel angulado 24 puertos 1RU | AG22: =Catalogo!$D22&"" -> Panduit | AH22: =Catalogo!$E22&"" -> CPPA24FMWBLY | AI22: =SUM(INICIO_TR:FIN_TR!$BA$22) -> 0
C23: LISTA DE MATERIALES | AA23: =Proyecto!$C23&"" -> S | AB23: =Proyecto!$D23&"" -> Audio / video IP | AC23: =SUM(INICIO_TR:FIN_TR!$AQ$23) -> 0 | AE23: =Catalogo!$B23&"" -> Patch panel cobre | AF23: =Catalogo!$C23&"" -> Patch panel angulado 48 puertos 2RU | AG23: =Catalogo!$D23&"" -> Panduit | AH23: =Catalogo!$E23&"" -> CPPA48FMWBLY | AI23: =SUM(INICIO_TR:FIN_TR!$BA$23) -> 0
C24: Categoría | D24: Descripción | E24: Marca | F24: Número de parte | G24: Cantidad | AA24: =Proyecto!$C24&"" -> G | AB24: =Proyecto!$D24&"" -> Gateways | AC24: =SUM(INICIO_TR:FIN_TR!$AQ$24) -> 0 | AE24: =Catalogo!$B24&"" -> Patch panel cobre | AF24: =Catalogo!$C24&"" -> Patch panel alta densidad plano 48 puertos 1RU | AG24: =Catalogo!$D24&"" -> Panduit | AH24: =Catalogo!$E24&"" -> CPP48HDWBLY | AI24: =SUM(INICIO_TR:FIN_TR!$BA$24) -> 0
C25: Rack | D25: Rack 2 postes 45RU aluminio, canal 3", rosca #12-24 | E25: Panduit | F25: R2P | G25: 1 | AA25: =Proyecto!$C25&"" -> R | AB25: =Proyecto!$D25&"" -> GRMS | AC25: =SUM(INICIO_TR:FIN_TR!$AQ$25) -> 0 | AE25: =Catalogo!$B25&"" -> Patch panel cobre | AF25: =Catalogo!$C25&"" -> Patch panel alta densidad angulado 48 puertos 1RU | AG25: =Catalogo!$D25&"" -> Panduit | AH25: =Catalogo!$E25&"" -> CPPA48HDWBLY | AI25: =SUM(INICIO_TR:FIN_TR!$BA$25) -> 0
C26: Organizador vertical | D26: Org. vertical 6" frontal/posterior (PatchRunner 2) | E26: Panduit | F26: PR2VD06 | G26: 2 | AA26: =Proyecto!$C26&"" | AB26: =Proyecto!$D26&"" | AC26: =SUM(INICIO_TR:FIN_TR!$AQ$26) -> 0 | AE26: =Catalogo!$B26&"" -> Organizador horizontal | AF26: =Catalogo!$C26&"" -> Org. horizontal 1RU frontal | AG26: =Catalogo!$D26&"" -> Panduit | AH26: =Catalogo!$E26&"" -> NMF1 | AI26: =SUM(INICIO_TR:FIN_TR!$BA$26) -> 0
C27: Patch panel cobre | D27: Patch panel plano 48 puertos 2RU | E27: Panduit | F27: CPP48FMWBLY | G27: 1 | AA27: =Proyecto!$C27&"" -> - | AB27: =Proyecto!$D27&"" -> Puerto sin salida (anula el tipo del panel) | AC27: =SUM(INICIO_TR:FIN_TR!$AQ$27) -> 0 | AE27: =Catalogo!$B27&"" -> Organizador horizontal | AF27: =Catalogo!$C27&"" -> Org. horizontal 1RU frontal/posterior | AG27: =Catalogo!$D27&"" -> Panduit | AH27: =Catalogo!$E27&"" -> NM1 | AI27: =SUM(INICIO_TR:FIN_TR!$BA$27) -> 0
C28: Jack | D28: Jack Cat 6A UTP azul (Mini-Com TX6A) | E28: Panduit | F28: CJ6X88TGBU | G28: 2 | AE28: =Catalogo!$B28&"" -> Organizador horizontal | AF28: =Catalogo!$C28&"" -> Org. horizontal 2RU frontal | AG28: =Catalogo!$D28&"" -> Panduit | AH28: =Catalogo!$E28&"" -> NMF2 | AI28: =SUM(INICIO_TR:FIN_TR!$BA$28) -> 0
AE29: =Catalogo!$B29&"" -> Organizador horizontal | AF29: =Catalogo!$C29&"" -> Org. horizontal 2RU frontal/posterior | AG29: =Catalogo!$D29&"" -> Panduit | AH29: =Catalogo!$E29&"" -> NM2 | AI29: =SUM(INICIO_TR:FIN_TR!$BA$29) -> 0
AE30: =Catalogo!$B30&"" -> Organizador horizontal | AF30: =Catalogo!$C30&"" -> Org. horizontal 1RU frontal (NetRunner) | AG30: =Catalogo!$D30&"" -> Panduit | AH30: =Catalogo!$E30&"" -> WMPFSE | AI30: =SUM(INICIO_TR:FIN_TR!$BA$30) -> 0
AE31: =Catalogo!$B31&"" -> Organizador horizontal | AF31: =Catalogo!$C31&"" -> Org. horizontal 2RU frontal (NetRunner) | AG31: =Catalogo!$D31&"" -> Panduit | AH31: =Catalogo!$E31&"" -> WMPF1E | AI31: =SUM(INICIO_TR:FIN_TR!$BA$31) -> 0
AE32: =Catalogo!$B32&"" -> Organizador horizontal | AF32: =Catalogo!$C32&"" -> Org. horizontal 1RU frontal/posterior (NetRunner) | AG32: =Catalogo!$D32&"" -> Panduit | AH32: =Catalogo!$E32&"" -> WMPSE | AI32: =SUM(INICIO_TR:FIN_TR!$BA$32) -> 0
AE33: =Catalogo!$B33&"" -> Organizador horizontal | AF33: =Catalogo!$C33&"" -> Org. horizontal 2RU frontal/posterior (NetRunner) | AG33: =Catalogo!$D33&"" -> Panduit | AH33: =Catalogo!$E33&"" -> WMP1E | AI33: =SUM(INICIO_TR:FIN_TR!$BA$33) -> 0
AE34: =Catalogo!$B34&"" -> Fibra | AF34: =Catalogo!$C34&"" -> Bandeja de fibra 1RU (4 cassettes/FAP, 96 fibras) | AG34: =Catalogo!$D34&"" -> Panduit | AH34: =Catalogo!$E34&"" -> FCE1U | AI34: =SUM(INICIO_TR:FIN_TR!$BA$34) -> 0
AE35: =Catalogo!$B35&"" -> Fibra | AF35: =Catalogo!$C35&"" -> Bandeja de fibra 2RU (8 cassettes/FAP, 192 fibras) | AG35: =Catalogo!$D35&"" -> Panduit | AH35: =Catalogo!$E35&"" -> FCE2U | AI35: =SUM(INICIO_TR:FIN_TR!$BA$35) -> 0
AE36: =Catalogo!$B36&"" -> Fibra | AF36: =Catalogo!$C36&"" -> Bandeja de fibra 4RU (12 cassettes/FAP, 288 fibras) | AG36: =Catalogo!$D36&"" -> Panduit | AH36: =Catalogo!$E36&"" -> FCE4U | AI36: =SUM(INICIO_TR:FIN_TR!$BA$36) -> 0
AE37: =Catalogo!$B37&"" -> Switch | AF37: =Catalogo!$C37&"" -> Switch Cisco 24p 1G (C9200L-24T-4G) | AG37: =Catalogo!$D37&"" -> Cisco | AH37: =Catalogo!$E37&"" -> C9200L-24T-4G | AI37: =SUM(INICIO_TR:FIN_TR!$BA$37) -> 0
AE38: =Catalogo!$B38&"" -> Switch | AF38: =Catalogo!$C38&"" -> Switch Cisco 24p 1G PoE+ (C9200L-24P-4G) | AG38: =Catalogo!$D38&"" -> Cisco | AH38: =Catalogo!$E38&"" -> C9200L-24P-4G | AI38: =SUM(INICIO_TR:FIN_TR!$BA$38) -> 0
AE39: =Catalogo!$B39&"" -> Switch | AF39: =Catalogo!$C39&"" -> Switch Cisco 48p 1G (C9200L-48T-4G) | AG39: =Catalogo!$D39&"" -> Cisco | AH39: =Catalogo!$E39&"" -> C9200L-48T-4G | AI39: =SUM(INICIO_TR:FIN_TR!$BA$39) -> 0
AE40: =Catalogo!$B40&"" -> Switch | AF40: =Catalogo!$C40&"" -> Switch Cisco 48p 1G PoE+ (C9200L-48P-4G) | AG40: =Catalogo!$D40&"" -> Cisco | AH40: =Catalogo!$E40&"" -> C9200L-48P-4G | AI40: =SUM(INICIO_TR:FIN_TR!$BA$40) -> 0
AE41: =Catalogo!$B41&"" -> Switch | AF41: =Catalogo!$C41&"" -> Switch Cisco 24p PoE+ 10G uplink (C9200L-24P-4X) | AG41: =Catalogo!$D41&"" -> Cisco | AH41: =Catalogo!$E41&"" -> C9200L-24P-4X | AI41: =SUM(INICIO_TR:FIN_TR!$BA$41) -> 0
AE42: =Catalogo!$B42&"" -> Switch | AF42: =Catalogo!$C42&"" -> Switch Cisco 48p PoE+ 10G uplink (C9200L-48P-4X) | AG42: =Catalogo!$D42&"" -> Cisco | AH42: =Catalogo!$E42&"" -> C9200L-48P-4X | AI42: =SUM(INICIO_TR:FIN_TR!$BA$42) -> 0
...

Sheet Catalogo
B2: CATÁLOGO DE EQUIPOS
B3: Panduit fabrica la infraestructura pasiva (racks, patch panels, jacks, organizadores, fibra). Equipo activo: switches Cisco, CCTV Axis, control de acceso Kantech / Software House. PDU, servidores y similares quedan "Por definir".
B4: EQUIPOS | D4: / Equipment | N4: Datos eléctricos y térmicos — valores típicos de planificación, NO de fabricante: confirmar con la hoja técnica
B5: Categoría | C5: Descripción | D5: Marca | E5: Número de parte | F5: RU | G5: Puertos | H5: Especificación / notas | N5: Consumo típico (W) | O5: Calor (BTU/h) | P5: Peso (kg) | Q5: Capacidad de suministro (W)
B6: Rack | C6: Rack 2 postes 45RU aluminio, canal 3", rosca #12-24 | D6: Panduit | E6: R2P | F6: 45 | H6: EIA-310, 19"; 84" (2134 mm) alto; carga UL 1000 lb | I6: =IF(AND($C6<>"",N($F6)>0,NOT(OR($B6="Rack",$B6="Gabinete",$B6="Rack de pared",$B6="Gabinete de pared"))),MAX($I$5:$I5)+1,"") | J6: =IF(OR($B6="Rack",$B6="Gabinete",$B6="Rack de pared",$B6="Gabinete de pared"),MAX($J$5:$J5)+1,"") -> 1 | K6: =IF($B6="Organizador vertical",COUNTIF($B$6:$B6,"Organizador vertical"),"") | L6: =IF($B6="Jack",COUNTIF($B$6:$B6,"Jack"),"") | M6: =IF(AND($C6<>"",N($F6)=0,$B6<>"Rack",$B6<>"Gabinete",$B6<>"Organizador vertical",$B6<>"Jack"),MAX($M$5:$M5)+1,"") | N6: 0 | O6: =IF(N6="","",ROUND(N6*3.412,0)) -> 0
B7: Rack | C7: Rack 2 postes 45RU acero, canal 3" | D7: Panduit | E7: R2PS | F7: 45 | H7: 19"; 84" (2134 mm) alto | I7: =IF(AND($C7<>"",N($F7)>0,NOT(OR($B7="Rack",$B7="Gabinete",$B7="Rack de pared",$B7="Gabinete de pared"))),MAX($I$5:$I6)+1,"") | J7: =IF(OR($B7="Rack",$B7="Gabinete",$B7="Rack de pared",$B7="Gabinete de pared"),MAX($J$5:$J6)+1,"") -> 2 | K7: =IF($B7="Organizador vertical",COUNTIF($B$6:$B7,"Organizador vertical"),"") | L7: =IF($B7="Jack",COUNTIF($B$6:$B7,"Jack"),"") | M7: =IF(AND($C7<>"",N($F7)=0,$B7<>"Rack",$B7<>"Gabinete",$B7<>"Organizador vertical",$B7<>"Jack"),MAX($M$5:$M6)+1,"") | N7: 0 | O7: =IF(N7="","",ROUND(N7*3.412,0)) -> 0
B8: Rack | C8: Rack 2 postes 45RU acero, canal 6" | D8: Panduit | E8: R2P6S | F8: 45 | H8: 19"; canal 6"; carga UL 1500 lb | I8: =IF(AND($C8<>"",N($F8)>0,NOT(OR($B8="Rack",$B8="Gabinete",$B8="Rack de pared",$B8="Gabinete de pared"))),MAX($I$5:$I7)+1,"") | J8: =IF(OR($B8="Rack",$B8="Gabinete",$B8="Rack de pared",$B8="Gabinete de pared"),MAX($J$5:$J7)+1,"") -> 3 | K8: =IF($B8="Organizador vertical",COUNTIF($B$6:$B8,"Organizador vertical"),"") | L8: =IF($B8="Jack",COUNTIF($B$6:$B8,"Jack"),"") | M8: =IF(AND($C8<>"",N($F8)=0,$B8<>"Rack",$B8<>"Gabinete",$B8<>"Organizador vertical",$B8<>"Jack"),MAX($M$5:$M7)+1,"") | N8: 0 | O8: =IF(N8="","",ROUND(N8*3.412,0)) -> 0
B9: Rack | C9: Rack 2 postes 42RU aluminio, canal 3" | D9: Panduit | E9: R2P79 | F9: 42 | H9: 79" (2007 mm) alto | I9: =IF(AND($C9<>"",N($F9)>0,NOT(OR($B9="Rack",$B9="Gabinete",$B9="Rack de pared",$B9="Gabinete de pared"))),MAX($I$5:$I8)+1,"") | J9: =IF(OR($B9="Rack",$B9="Gabinete",$B9="Rack de pared",$B9="Gabinete de pared"),MAX($J$5:$J8)+1,"") -> 4 | K9: =IF($B9="Organizador vertical",COUNTIF($B$6:$B9,"Organizador vertical"),"") | L9: =IF($B9="Jack",COUNTIF($B$6:$B9,"Jack"),"") | M9: =IF(AND($C9<>"",N($F9)=0,$B9<>"Rack",$B9<>"Gabinete",$B9<>"Organizador vertical",$B9<>"Jack"),MAX($M$5:$M8)+1,"") | N9: 0 | O9: =IF(N9="","",ROUND(N9*3.412,0)) -> 0
B10: Organizador vertical | C10: Org. vertical 6" frontal (PatchRunner 2) | D10: Panduit | E10: PR2VFD06 | H10: Para rack 2 postes, 45RU | I10: =IF(AND($C10<>"",N($F10)>0,NOT(OR($B10="Rack",$B10="Gabinete",$B10="Rack de pared",$B10="Gabinete de pared"))),MAX($I$5:$I9)+1,"") | J10: =IF(OR($B10="Rack",$B10="Gabinete",$B10="Rack de pared",$B10="Gabinete de pared"),MAX($J$5:$J9)+1,"") | K10: =IF($B10="Organizador vertical",COUNTIF($B$6:$B10,"Organizador vertical"),"") -> 1 | L10: =IF($B10="Jack",COUNTIF($B$6:$B10,"Jack"),"") | M10: =IF(AND($C10<>"",N($F10)=0,$B10<>"Rack",$B10<>"Gabinete",$B10<>"Organizador vertical",$B10<>"Jack"),MAX($M$5:$M9)+1,"") | N10: 0 | O10: =IF(N10="","",ROUND(N10*3.412,0)) -> 0
B11: Organizador vertical | C11: Org. vertical 8" frontal (PatchRunner 2) | D11: Panduit | E11: PR2VFD08 | H11: Para rack 2 postes, 45RU | I11: =IF(AND($C11<>"",N($F11)>0,NOT(OR($B11="Rack",$B11="Gabinete",$B11="Rack de pared",$B11="Gabinete de pared"))),MAX($I$5:$I10)+1,"") | J11: =IF(OR($B11="Rack",$B11="Gabinete",$B11="Rack de pared",$B11="Gabinete de pared"),MAX($J$5:$J10)+1,"") | K11: =IF($B11="Organizador vertical",COUNTIF($B$6:$B11,"Organizador vertical"),"") -> 2 | L11: =IF($B11="Jack",COUNTIF($B$6:$B11,"Jack"),"") | M11: =IF(AND($C11<>"",N($F11)=0,$B11<>"Rack",$B11<>"Gabinete",$B11<>"Organizador vertical",$B11<>"Jack"),MAX($M$5:$M10)+1,"") | N11: 0 | O11: =IF(N11="","",ROUND(N11*3.412,0)) -> 0
B12: Organizador vertical | C12: Org. vertical 10" frontal (PatchRunner 2) | D12: Panduit | E12: PR2VFD10 | H12: Para rack 2 postes, 45RU | I12: =IF(AND($C12<>"",N($F12)>0,NOT(OR($B12="Rack",$B12="Gabinete",$B12="Rack de pared",$B12="Gabinete de pared"))),MAX($I$5:$I11)+1,"") | J12: =IF(OR($B12="Rack",$B12="Gabinete",$B12="Rack de pared",$B12="Gabinete de pared"),MAX($J$5:$J11)+1,"") | K12: =IF($B12="Organizador vertical",COUNTIF($B$6:$B12,"Organizador vertical"),"") -> 3 | L12: =IF($B12="Jack",COUNTIF($B$6:$B12,"Jack"),"") | M12: =IF(AND($C12<>"",N($F12)=0,$B12<>"Rack",$B12<>"Gabinete",$B12<>"Organizador vertical",$B12<>"Jack"),MAX($M$5:$M11)+1,"") | N12: 0 | O12: =IF(N12="","",ROUND(N12*3.412,0)) -> 0
B13: Organizador vertical | C13: Org. vertical 12" frontal (PatchRunner 2) | D13: Panduit | E13: PR2VFD12 | H13: Para rack 2 postes, 45RU | I13: =IF(AND($C13<>"",N($F13)>0,NOT(OR($B13="Rack",$B13="Gabinete",$B13="Rack de pared",$B13="Gabinete de pared"))),MAX($I$5:$I12)+1,"") | J13: =IF(OR($B13="Rack",$B13="Gabinete",$B13="Rack de pared",$B13="Gabinete de pared"),MAX($J$5:$J12)+1,"") | K13: =IF($B13="Organizador vertical",COUNTIF($B$6:$B13,"Organizador vertical"),"") -> 4 | L13: =IF($B13="Jack",COUNTIF($B$6:$B13,"Jack"),"") | M13: =IF(AND($C13<>"",N($F13)=0,$B13<>"Rack",$B13<>"Gabinete",$B13<>"Organizador vertical",$B13<>"Jack"),MAX($M$5:$M12)+1,"") | N13: 0 | O13: =IF(N13="","",ROUND(N13*3.412,0)) -> 0
B14: Organizador vertical | C14: Org. vertical 6" frontal/posterior (PatchRunner 2) | D14: Panduit | E14: PR2VD06 | H14: Para rack 2 postes, 45RU | I14: =IF(AND($C14<>"",N($F14)>0,NOT(OR($B14="Rack",$B14="Gabinete",$B14="Rack de pared",$B14="Gabinete de pared"))),MAX($I$5:$I13)+1,"") | J14: =IF(OR($B14="Rack",$B14="Gabinete",$B14="Rack de pared",$B14="Gabinete de pared"),MAX($J$5:$J13)+1,"") | K14: =IF($B14="Organizador vertical",COUNTIF($B$6:$B14,"Organizador vertical"),"") -> 5 | L14: =IF($B14="Jack",COUNTIF($B$6:$B14,"Jack"),"") | M14: =IF(AND($C14<>"",N($F14)=0,$B14<>"Rack",$B14<>"Gabinete",$B14<>"Organizador vertical",$B14<>"Jack"),MAX($M$5:$M13)+1,"") | N14: 0 | O14: =IF(N14="","",ROUND(N14*3.412,0)) -> 0
B15: Organizador vertical | C15: Org. vertical 8" frontal/posterior (PatchRunner 2) | D15: Panduit | E15: PR2VD08 | H15: Para rack 2 postes, 45RU | I15: =IF(AND($C15<>"",N($F15)>0,NOT(OR($B15="Rack",$B15="Gabinete",$B15="Rack de pared",$B15="Gabinete de pared"))),MAX($I$5:$I14)+1,"") | J15: =IF(OR($B15="Rack",$B15="Gabinete",$B15="Rack de pared",$B15="Gabinete de pared"),MAX($J$5:$J14)+1,"") | K15: =IF($B15="Organizador vertical",COUNTIF($B$6:$B15,"Organizador vertical"),"") -> 6 | L15: =IF($B15="Jack",COUNTIF($B$6:$B15,"Jack"),"") | M15: =IF(AND($C15<>"",N($F15)=0,$B15<>"Rack",$B15<>"Gabinete",$B15<>"Organizador vertical",$B15<>"Jack"),MAX($M$5:$M14)+1,"") | N15: 0 | O15: =IF(N15="","",ROUND(N15*3.412,0)) -> 0
B16: Organizador vertical | C16: Org. vertical 10" frontal/posterior (PatchRunner 2) | D16: Panduit | E16: PR2VD10 | H16: Para rack 2 postes, 45RU | I16: =IF(AND($C16<>"",N($F16)>0,NOT(OR($B16="Rack",$B16="Gabinete",$B16="Rack de pared",$B16="Gabinete de pared"))),MAX($I$5:$I15)+1,"") | J16: =IF(OR($B16="Rack",$B16="Gabinete",$B16="Rack de pared",$B16="Gabinete de pared"),MAX($J$5:$J15)+1,"") | K16: =IF($B16="Organizador vertical",COUNTIF($B$6:$B16,"Organizador vertical"),"") -> 7 | L16: =IF($B16="Jack",COUNTIF($B$6:$B16,"Jack"),"") | M16: =IF(AND($C16<>"",N($F16)=0,$B16<>"Rack",$B16<>"Gabinete",$B16<>"Organizador vertical",$B16<>"Jack"),MAX($M$5:$M15)+1,"") | N16: 0 | O16: =IF(N16="","",ROUND(N16*3.412,0)) -> 0
B17: Organizador vertical | C17: Org. vertical 12" frontal/posterior (PatchRunner 2) | D17: Panduit | E17: PR2VD12 | H17: Para rack 2 postes, 45RU | I17: =IF(AND($C17<>"",N($F17)>0,NOT(OR($B17="Rack",$B17="Gabinete",$B17="Rack de pared",$B17="Gabinete de pared"))),MAX($I$5:$I16)+1,"") | J17: =IF(OR($B17="Rack",$B17="Gabinete",$B17="Rack de pared",$B17="Gabinete de pared"),MAX($J$5:$J16)+1,"") | K17: =IF($B17="Organizador vertical",COUNTIF($B$6:$B17,"Organizador vertical"),"") -> 8 | L17: =IF($B17="Jack",COUNTIF($B$6:$B17,"Jack"),"") | M17: =IF(AND($C17<>"",N($F17)=0,$B17<>"Rack",$B17<>"Gabinete",$B17<>"Organizador vertical",$B17<>"Jack"),MAX($M$5:$M16)+1,"") | N17: 0 | O17: =IF(N17="","",ROUND(N17*3.412,0)) -> 0
B18: Organizador vertical | C18: Org. vertical 4.9" frontal/posterior (NetRunner) | D18: Panduit | E18: WMPV45E | H18: 45RU | I18: =IF(AND($C18<>"",N($F18)>0,NOT(OR($B18="Rack",$B18="Gabinete",$B18="Rack de pared",$B18="Gabinete de pared"))),MAX($I$5:$I17)+1,"") | J18: =IF(OR($B18="Rack",$B18="Gabinete",$B18="Rack de pared",$B18="Gabinete de pared"),MAX($J$5:$J17)+1,"") | K18: =IF($B18="Organizador vertical",COUNTIF($B$6:$B18,"Organizador vertical"),"") -> 9 | L18: =IF($B18="Jack",COUNTIF($B$6:$B18,"Jack"),"") | M18: =IF(AND($C18<>"",N($F18)=0,$B18<>"Rack",$B18<>"Gabinete",$B18<>"Organizador vertical",$B18<>"Jack"),MAX($M$5:$M17)+1,"") | N18: 0 | O18: =IF(N18="","",ROUND(N18*3.412,0)) -> 0
B19: Organizador vertical | C19: Org. vertical 6.7" frontal/posterior (NetRunner) | D19: Panduit | E19: WMPVHC45E | H19: 45RU, alta capacidad | I19: =IF(AND($C19<>"",N($F19)>0,NOT(OR($B19="Rack",$B19="Gabinete",$B19="Rack de pared",$B19="Gabinete de pared"))),MAX($I$5:$I18)+1,"") | J19: =IF(OR($B19="Rack",$B19="Gabinete",$B19="Rack de pared",$B19="Gabinete de pared"),MAX($J$5:$J18)+1,"") | K19: =IF($B19="Organizador vertical",COUNTIF($B$6:$B19,"Organizador vertical"),"") -> 10 | L19: =IF($B19="Jack",COUNTIF($B$6:$B19,"Jack"),"") | M19: =IF(AND($C19<>"",N($F19)=0,$B19<>"Rack",$B19<>"Gabinete",$B19<>"Organizador vertical",$B19<>"Jack"),MAX($M$5:$M18)+1,"") | N19: 0 | O19: =IF(N19="","",ROUND(N19*3.412,0)) -> 0
B20: Patch panel cobre | C20: Patch panel plano 24 puertos 1RU | D20: Panduit | E20: CPP24FMWBLY | F20: 1 | G20: 24 | H20: Mini-Com modular, montaje al ras | I20: =IF(AND($C20<>"",N($F20)>0,NOT(OR($B20="Rack",$B20="Gabinete",$B20="Rack de pared",$B20="Gabinete de pared"))),MAX($I$5:$I19)+1,"") -> 1 | J20: =IF(OR($B20="Rack",$B20="Gabinete",$B20="Rack de pared",$B20="Gabinete de pared"),MAX($J$5:$J19)+1,"") | K20: =IF($B20="Organizador vertical",COUNTIF($B$6:$B20,"Organizador vertical"),"") | L20: =IF($B20="Jack",COUNTIF($B$6:$B20,"Jack"),"") | M20: =IF(AND($C20<>"",N($F20)=0,$B20<>"Rack",$B20<>"Gabinete",$B20<>"Organizador vertical",$B20<>"Jack"),MAX($M$5:$M19)+1,"") | N20: 0 | O20: =IF(N20="","",ROUND(N20*3.412,0)) -> 0 | P20: 1
B21: Patch panel cobre | C21: Patch panel plano 48 puertos 2RU | D21: Panduit | E21: CPP48FMWBLY | F21: 2 | G21: 48 | H21: Mini-Com modular, montaje al ras | I21: =IF(AND($C21<>"",N($F21)>0,NOT(OR($B21="Rack",$B21="Gabinete",$B21="Rack de pared",$B21="Gabinete de pared"))),MAX($I$5:$I20)+1,"") -> 2 | J21: =IF(OR($B21="Rack",$B21="Gabinete",$B21="Rack de pared",$B21="Gabinete de pared"),MAX($J$5:$J20)+1,"") | K21: =IF($B21="Organizador vertical",COUNTIF($B$6:$B21,"Organizador vertical"),"") | L21: =IF($B21="Jack",COUNTIF($B$6:$B21,"Jack"),"") | M21: =IF(AND($C21<>"",N($F21)=0,$B21<>"Rack",$B21<>"Gabinete",$B21<>"Organizador vertical",$B21<>"Jack"),MAX($M$5:$M20)+1,"") | N21: 0 | O21: =IF(N21="","",ROUND(N21*3.412,0)) -> 0 | P21: 2
B22: Patch panel cobre | C22: Patch panel angulado 24 puertos 1RU | D22: Panduit | E22: CPPA24FMWBLY | F22: 1 | G22: 24 | H22: Mini-Com modular angulado | I22: =IF(AND($C22<>"",N($F22)>0,NOT(OR($B22="Rack",$B22="Gabinete",$B22="Rack de pared",$B22="Gabinete de pared"))),MAX($I$5:$I21)+1,"") -> 3 | J22: =IF(OR($B22="Rack",$B22="Gabinete",$B22="Rack de pared",$B22="Gabinete de pared"),MAX($J$5:$J21)+1,"") | K22: =IF($B22="Organizador vertical",COUNTIF($B$6:$B22,"Organizador vertical"),"") | L22: =IF($B22="Jack",COUNTIF($B$6:$B22,"Jack"),"") | M22: =IF(AND($C22<>"",N($F22)=0,$B22<>"Rack",$B22<>"Gabinete",$B22<>"Organizador vertical",$B22<>"Jack"),MAX($M$5:$M21)+1,"") | N22: 0 | O22: =IF(N22="","",ROUND(N22*3.412,0)) -> 0 | P22: 1
B23: Patch panel cobre | C23: Patch panel angulado 48 puertos 2RU | D23: Panduit | E23: CPPA48FMWBLY | F23: 2 | G23: 48 | H23: Mini-Com modular angulado | I23: =IF(AND($C23<>"",N($F23)>0,NOT(OR($B23="Rack",$B23="Gabinete",$B23="Rack de pared",$B23="Gabinete de pared"))),MAX($I$5:$I22)+1,"") -> 4 | J23: =IF(OR($B23="Rack",$B23="Gabinete",$B23="Rack de pared",$B23="Gabinete de pared"),MAX($J$5:$J22)+1,"") | K23: =IF($B23="Organizador vertical",COUNTIF($B$6:$B23,"Organizador vertical"),"") | L23: =IF($B23="Jack",COUNTIF($B$6:$B23,"Jack"),"") | M23: =IF(AND($C23<>"",N($F23)=0,$B23<>"Rack",$B23<>"Gabinete",$B23<>"Organizador vertical",$B23<>"Jack"),MAX($M$5:$M22)+1,"") | N23: 0 | O23: =IF(N23="","",ROUND(N23*3.412,0)) -> 0 | P23: 2
B24: Patch panel cobre | C24: Patch panel alta densidad plano 48 puertos 1RU | D24: Panduit | E24: CPP48HDWBLY | F24: 1 | G24: 48 | H24: Mini-Com HD, 48 puertos por RU | I24: =IF(AND($C24<>"",N($F24)>0,NOT(OR($B24="Rack",$B24="Gabinete",$B24="Rack de pared",$B24="Gabinete de pared"))),MAX($I$5:$I23)+1,"") -> 5 | J24: =IF(OR($B24="Rack",$B24="Gabinete",$B24="Rack de pared",$B24="Gabinete de pared"),MAX($J$5:$J23)+1,"") | K24: =IF($B24="Organizador vertical",COUNTIF($B$6:$B24,"Organizador vertical"),"") | L24: =IF($B24="Jack",COUNTIF($B$6:$B24,"Jack"),"") | M24: =IF(AND($C24<>"",N($F24)=0,$B24<>"Rack",$B24<>"Gabinete",$B24<>"Organizador vertical",$B24<>"Jack"),MAX($M$5:$M23)+1,"") | N24: 0 | O24: =IF(N24="","",ROUND(N24*3.412,0)) -> 0 | P24: 1.5
B25: Patch panel cobre | C25: Patch panel alta densidad angulado 48 puertos 1RU | D25: Panduit | E25: CPPA48HDWBLY | F25: 1 | G25: 48 | H25: Mini-Com HD angulado | I25: =IF(AND($C25<>"",N($F25)>0,NOT(OR($B25="Rack",$B25="Gabinete",$B25="Rack de pared",$B25="Gabinete de pared"))),MAX($I$5:$I24)+1,"") -> 6 | J25: =IF(OR($B25="Rack",$B25="Gabinete",$B25="Rack de pared",$B25="Gabinete de pared"),MAX($J$5:$J24)+1,"") | K25: =IF($B25="Organizador vertical",COUNTIF($B$6:$B25,"Organizador vertical"),"") | L25: =IF($B25="Jack",COUNTIF($B$6:$B25,"Jack"),"") | M25: =IF(AND($C25<>"",N($F25)=0,$B25<>"Rack",$B25<>"Gabinete",$B25<>"Organizador vertical",$B25<>"Jack"),MAX($M$5:$M24)+1,"") | N25: 0 | O25: =IF(N25="","",ROUND(N25*3.412,0)) -> 0 | P25: 1.5
B26: Organizador horizontal | C26: Org. horizontal 1RU frontal | D26: Panduit | E26: NMF1 | F26: 1 | H26: NetManager | I26: =IF(AND($C26<>"",N($F26)>0,NOT(OR($B26="Rack",$B26="Gabinete",$B26="Rack de pared",$B26="Gabinete de pared"))),MAX($I$5:$I25)+1,"") -> 7 | J26: =IF(OR($B26="Rack",$B26="Gabinete",$B26="Rack de pared",$B26="Gabinete de pared"),MAX($J$5:$J25)+1,"") | K26: =IF($B26="Organizador vertical",COUNTIF($B$6:$B26,"Organizador vertical"),"") | L26: =IF($B26="Jack",COUNTIF($B$6:$B26,"Jack"),"") | M26: =IF(AND($C26<>"",N($F26)=0,$B26<>"Rack",$B26<>"Gabinete",$B26<>"Organizador vertical",$B26<>"Jack"),MAX($M$5:$M25)+1,"") | N26: 0 | O26: =IF(N26="","",ROUND(N26*3.412,0)) -> 0 | P26: 1
B27: Organizador horizontal | C27: Org. horizontal 1RU frontal/posterior | D27: Panduit | E27: NM1 | F27: 1 | H27: NetManager | I27: =IF(AND($C27<>"",N($F27)>0,NOT(OR($B27="Rack",$B27="Gabinete",$B27="Rack de pared",$B27="Gabinete de pared"))),MAX($I$5:$I26)+1,"") -> 8 | J27: =IF(OR($B27="Rack",$B27="Gabinete",$B27="Rack de pared",$B27="Gabinete de pared"),MAX($J$5:$J26)+1,"") | K27: =IF($B27="Organizador vertical",COUNTIF($B$6:$B27,"Organizador vertical"),"") | L27: =IF($B27="Jack",COUNTIF($B$6:$B27,"Jack"),"") | M27: =IF(AND($C27<>"",N($F27)=0,$B27<>"Rack",$B27<>"Gabinete",$B27<>"Organizador vertical",$B27<>"Jack"),MAX($M$5:$M26)+1,"") | N27: 0 | O27: =IF(N27="","",ROUND(N27*3.412,0)) -> 0 | P27: 1
B28: Organizador horizontal | C28: Org. horizontal 2RU frontal | D28: Panduit | E28: NMF2 | F28: 2 | H28: NetManager | I28: =IF(AND($C28<>"",N($F28)>0,NOT(OR($B28="Rack",$B28="Gabinete",$B28="Rack de pared",$B28="Gabinete de pared"))),MAX($I$5:$I27)+1,"") -> 9 | J28: =IF(OR($B28="Rack",$B28="Gabinete",$B28="Rack de pared",$B28="Gabinete de pared"),MAX($J$5:$J27)+1,"") | K28: =IF($B28="Organizador vertical",COUNTIF($B$6:$B28,"Organizador vertical"),"") | L28: =IF($B28="Jack",COUNTIF($B$6:$B28,"Jack"),"") | M28: =IF(AND($C28<>"",N($F28)=0,$B28<>"Rack",$B28<>"Gabinete",$B28<>"Organizador vertical",$B28<>"Jack"),MAX($M$5:$M27)+1,"") | N28: 0 | O28: =IF(N28="","",ROUND(N28*3.412,0)) -> 0 | P28: 2
B29: Organizador horizontal | C29: Org. horizontal 2RU frontal/posterior | D29: Panduit | E29: NM2 | F29: 2 | H29: NetManager | I29: =IF(AND($C29<>"",N($F29)>0,NOT(OR($B29="Rack",$B29="Gabinete",$B29="Rack de pared",$B29="Gabinete de pared"))),MAX($I$5:$I28)+1,"") -> 10 | J29: =IF(OR($B29="Rack",$B29="Gabinete",$B29="Rack de pared",$B29="Gabinete de pared"),MAX($J$5:$J28)+1,"") | K29: =IF($B29="Organizador vertical",COUNTIF($B$6:$B29,"Organizador vertical"),"") | L29: =IF($B29="Jack",COUNTIF($B$6:$B29,"Jack"),"") | M29: =IF(AND($C29<>"",N($F29)=0,$B29<>"Rack",$B29<>"Gabinete",$B29<>"Organizador vertical",$B29<>"Jack"),MAX($M$5:$M28)+1,"") | N29: 0 | O29: =IF(N29="","",ROUND(N29*3.412,0)) -> 0 | P29: 2
B30: Organizador horizontal | C30: Org. horizontal 1RU frontal (NetRunner) | D30: Panduit | E30: WMPFSE | F30: 1 | H30: NetRunner | I30: =IF(AND($C30<>"",N($F30)>0,NOT(OR($B30="Rack",$B30="Gabinete",$B30="Rack de pared",$B30="Gabinete de pared"))),MAX($I$5:$I29)+1,"") -> 11 | J30: =IF(OR($B30="Rack",$B30="Gabinete",$B30="Rack de pared",$B30="Gabinete de pared"),MAX($J$5:$J29)+1,"") | K30: =IF($B30="Organizador vertical",COUNTIF($B$6:$B30,"Organizador vertical"),"") | L30: =IF($B30="Jack",COUNTIF($B$6:$B30,"Jack"),"") | M30: =IF(AND($C30<>"",N($F30)=0,$B30<>"Rack",$B30<>"Gabinete",$B30<>"Organizador vertical",$B30<>"Jack"),MAX($M$5:$M29)+1,"") | N30: 0 | O30: =IF(N30="","",ROUND(N30*3.412,0)) -> 0 | P30: 1
B31: Organizador horizontal | C31: Org. horizontal 2RU frontal (NetRunner) | D31: Panduit | E31: WMPF1E | F31: 2 | H31: NetRunner | I31: =IF(AND($C31<>"",N($F31)>0,NOT(OR($B31="Rack",$B31="Gabinete",$B31="Rack de pared",$B31="Gabinete de pared"))),MAX($I$5:$I30)+1,"") -> 12 | J31: =IF(OR($B31="Rack",$B31="Gabinete",$B31="Rack de pared",$B31="Gabinete de pared"),MAX($J$5:$J30)+1,"") | K31: =IF($B31="Organizador vertical",COUNTIF($B$6:$B31,"Organizador vertical"),"") | L31: =IF($B31="Jack",COUNTIF($B$6:$B31,"Jack"),"") | M31: =IF(AND($C31<>"",N($F31)=0,$B31<>"Rack",$B31<>"Gabinete",$B31<>"Organizador vertical",$B31<>"Jack"),MAX($M$5:$M30)+1,"") | N31: 0 | O31: =IF(N31="","",ROUND(N31*3.412,0)) -> 0 | P31: 2
B32: Organizador horizontal | C32: Org. horizontal 1RU frontal/posterior (NetRunner) | D32: Panduit | E32: WMPSE | F32: 1 | H32: NetRunner | I32: =IF(AND($C32<>"",N($F32)>0,NOT(OR($B32="Rack",$B32="Gabinete",$B32="Rack de pared",$B32="Gabinete de pared"))),MAX($I$5:$I31)+1,"") -> 13 | J32: =IF(OR($B32="Rack",$B32="Gabinete",$B32="Rack de pared",$B32="Gabinete de pared"),MAX($J$5:$J31)+1,"") | K32: =IF($B32="Organizador vertical",COUNTIF($B$6:$B32,"Organizador vertical"),"") | L32: =IF($B32="Jack",COUNTIF($B$6:$B32,"Jack"),"") | M32: =IF(AND($C32<>"",N($F32)=0,$B32<>"Rack",$B32<>"Gabinete",$B32<>"Organizador vertical",$B32<>"Jack"),MAX($M$5:$M31)+1,"") | N32: 0 | O32: =IF(N32="","",ROUND(N32*3.412,0)) -> 0 | P32: 1
B33: Organizador horizontal | C33: Org. horizontal 2RU frontal/posterior (NetRunner) | D33: Panduit | E33: WMP1E | F33: 2 | H33: NetRunner | I33: =IF(AND($C33<>"",N($F33)>0,NOT(OR($B33="Rack",$B33="Gabinete",$B33="Rack de pared",$B33="Gabinete de pared"))),MAX($I$5:$I32)+1,"") -> 14 | J33: =IF(OR($B33="Rack",$B33="Gabinete",$B33="Rack de pared",$B33="Gabinete de pared"),MAX($J$5:$J32)+1,"") | K33: =IF($B33="Organizador vertical",COUNTIF($B$6:$B33,"Organizador vertical"),"") | L33: =IF($B33="Jack",COUNTIF($B$6:$B33,"Jack"),"") | M33: =IF(AND($C33<>"",N($F33)=0,$B33<>"Rack",$B33<>"Gabinete",$B33<>"Organizador vertical",$B33<>"Jack"),MAX($M$5:$M32)+1,"") | N33: 0 | O33: =IF(N33="","",ROUND(N33*3.412,0)) -> 0 | P33: 2
B34: Fibra | C34: Bandeja de fibra 1RU (4 cassettes/FAP, 96 fibras) | D34: Panduit | E34: FCE1U | F34: 1 | H34: Opticom QuickNet | I34: =IF(AND($C34<>"",N($F34)>0,NOT(OR($B34="Rack",$B34="Gabinete",$B34="Rack de pared",$B34="Gabinete de pared"))),MAX($I$5:$I33)+1,"") -> 15 | J34: =IF(OR($B34="Rack",$B34="Gabinete",$B34="Rack de pared",$B34="Gabinete de pared"),MAX($J$5:$J33)+1,"") | K34: =IF($B34="Organizador vertical",COUNTIF($B$6:$B34,"Organizador vertical"),"") | L34: =IF($B34="Jack",COUNTIF($B$6:$B34,"Jack"),"") | M34: =IF(AND($C34<>"",N($F34)=0,$B34<>"Rack",$B34<>"Gabinete",$B34<>"Organizador vertical",$B34<>"Jack"),MAX($M$5:$M33)+1,"") | N34: 0 | O34: =IF(N34="","",ROUND(N34*3.412,0)) -> 0 | P34: 3
B35: Fibra | C35: Bandeja de fibra 2RU (8 cassettes/FAP, 192 fibras) | D35: Panduit | E35: FCE2U | F35: 2 | H35: Opticom QuickNet | I35: =IF(AND($C35<>"",N($F35)>0,NOT(OR($B35="Rack",$B35="Gabinete",$B35="Rack de pared",$B35="Gabinete de pared"))),MAX($I$5:$I34)+1,"") -> 16 | J35: =IF(OR($B35="Rack",$B35="Gabinete",$B35="Rack de pared",$B35="Gabinete de pared"),MAX($J$5:$J34)+1,"") | K35: =IF($B35="Organizador vertical",COUNTIF($B$6:$B35,"Organizador vertical"),"") | L35: =IF($B35="Jack",COUNTIF($B$6:$B35,"Jack"),"") | M35: =IF(AND($C35<>"",N($F35)=0,$B35<>"Rack",$B35<>"Gabinete",$B35<>"Organizador vertical",$B35<>"Jack"),MAX($M$5:$M34)+1,"") | N35: 0 | O35: =IF(N35="","",ROUND(N35*3.412,0)) -> 0 | P35: 5
B36: Fibra | C36: Bandeja de fibra 4RU (12 cassettes/FAP, 288 fibras) | D36: Panduit | E36: FCE4U | F36: 4 | H36: Opticom QuickNet | I36: =IF(AND($C36<>"",N($F36)>0,NOT(OR($B36="Rack",$B36="Gabinete",$B36="Rack de pared",$B36="Gabinete de pared"))),MAX($I$5:$I35)+1,"") -> 17 | J36: =IF(OR($B36="Rack",$B36="Gabinete",$B36="Rack de pared",$B36="Gabinete de pared"),MAX($J$5:$J35)+1,"") | K36: =IF($B36="Organizador vertical",COUNTIF($B$6:$B36,"Organizador vertical"),"") | L36: =IF($B36="Jack",COUNTIF($B$6:$B36,"Jack"),"") | M36: =IF(AND($C36<>"",N($F36)=0,$B36<>"Rack",$B36<>"Gabinete",$B36<>"Organizador vertical",$B36<>"Jack"),MAX($M$5:$M35)+1,"") | N36: 0 | O36: =IF(N36="","",ROUND(N36*3.412,0)) -> 0 | P36: 8
B37: Switch | C37: Switch Cisco 24p 1G (C9200L-24T-4G) | D37: Cisco | E37: C9200L-24T-4G | F37: 1 | G37: 24 | H37: 24×1G datos, 4×1G uplink | I37: =IF(AND($C37<>"",N($F37)>0,NOT(OR($B37="Rack",$B37="Gabinete",$B37="Rack de pared",$B37="Gabinete de pared"))),MAX($I$5:$I36)+1,"") -> 18 | J37: =IF(OR($B37="Rack",$B37="Gabinete",$B37="Rack de pared",$B37="Gabinete de pared"),MAX($J$5:$J36)+1,"") | K37: =IF($B37="Organizador vertical",COUNTIF($B$6:$B37,"Organizador vertical"),"") | L37: =IF($B37="Jack",COUNTIF($B$6:$B37,"Jack"),"") | M37: =IF(AND($C37<>"",N($F37)=0,$B37<>"Rack",$B37<>"Gabinete",$B37<>"Organizador vertical",$B37<>"Jack"),MAX($M$5:$M36)+1,"") | N37: 45 | O37: =IF(N37="","",ROUND(N37*3.412,0)) -> 154 | P37: 4.5
B38: Switch | C38: Switch Cisco 24p 1G PoE+ (C9200L-24P-4G) | D38: Cisco | E38: C9200L-24P-4G | F38: 1 | G38: 24 | H38: 24×1G PoE+, 4×1G uplink, PoE 370 W (740 W con 2 fuentes) | I38: =IF(AND($C38<>"",N($F38)>0,NOT(OR($B38="Rack",$B38="Gabinete",$B38="Rack de pared",$B38="Gabinete de pared"))),MAX($I$5:$I37)+1,"") -> 19 | J38: =IF(OR($B38="Rack",$B38="Gabinete",$B38="Rack de pared",$B38="Gabinete de pared"),MAX($J$5:$J37)+1,"") | K38: =IF($B38="Organizador vertical",COUNTIF($B$6:$B38,"Organizador vertical"),"") | L38: =IF($B38="Jack",COUNTIF($B$6:$B38,"Jack"),"") | M38: =IF(AND($C38<>"",N($F38)=0,$B38<>"Rack",$B38<>"Gabinete",$B38<>"Organizador vertical",$B38<>"Jack"),MAX($M$5:$M37)+1,"") | N38: 70 | O38: =IF(N38="","",ROUND(N38*3.412,0)) -> 239 | P38: 4.5
B39: Switch | C39: Switch Cisco 48p 1G (C9200L-48T-4G) | D39: Cisco | E39: C9200L-48T-4G | F39: 1 | G39: 48 | H39: 48×1G datos, 4×1G uplink | I39: =IF(AND($C39<>"",N($F39)>0,NOT(OR($B39="Rack",$B39="Gabinete",$B39="Rack de pared",$B39="Gabinete de pared"))),MAX($I$5:$I38)+1,"") -> 20 | J39: =IF(OR($B39="Rack",$B39="Gabinete",$B39="Rack de pared",$B39="Gabinete de pared"),MAX($J$5:$J38)+1,"") | K39: =IF($B39="Organizador vertical",COUNTIF($B$6:$B39,"Organizador vertical"),"") | L39: =IF($B39="Jack",COUNTIF($B$6:$B39,"Jack"),"") | M39: =IF(AND($C39<>"",N($F39)=0,$B39<>"Rack",$B39<>"Gabinete",$B39<>"Organizador vertical",$B39<>"Jack"),MAX($M$5:$M38)+1,"") | N39: 75 | O39: =IF(N39="","",ROUND(N39*3.412,0)) -> 256 | P39: 6.5
B40: Switch | C40: Switch Cisco 48p 1G PoE+ (C9200L-48P-4G) | D40: Cisco | E40: C9200L-48P-4G | F40: 1 | G40: 48 | H40: 48×1G PoE+, 4×1G uplink, PoE 740 W (1440 W con 2 fuentes) | I40: =IF(AND($C40<>"",N($F40)>0,NOT(OR($B40="Rack",$B40="Gabinete",$B40="Rack de pared",$B40="Gabinete de pared"))),MAX($I$5:$I39)+1,"") -> 21 | J40: =IF(OR($B40="Rack",$B40="Gabinete",$B40="Rack de pared",$B40="Gabinete de pared"),MAX($J$5:$J39)+1,"") | K40: =IF($B40="Organizador vertical",COUNTIF($B$6:$B40,"Organizador vertical"),"") | L40: =IF($B40="Jack",COUNTIF($B$6:$B40,"Jack"),"") | M40: =IF(AND($C40<>"",N($F40)=0,$B40<>"Rack",$B40<>"Gabinete",$B40<>"Organizador vertical",$B40<>"Jack"),MAX($M$5:$M39)+1,"") | N40: 110 | O40: =IF(N40="","",ROUND(N40*3.412,0)) -> 375 | P40: 6.5
B41: Switch | C41: Switch Cisco 24p PoE+ 10G uplink (C9200L-24P-4X) | D41: Cisco | E41: C9200L-24P-4X | F41: 1 | G41: 24 | H41: 24×1G PoE+, 4×10G uplink, PoE 370 W | I41: =IF(AND($C41<>"",N($F41)>0,NOT(OR($B41="Rack",$B41="Gabinete",$B41="Rack de pared",$B41="Gabinete de pared"))),MAX($I$5:$I40)+1,"") -> 22 | J41: =IF(OR($B41="Rack",$B41="Gabinete",$B41="Rack de pared",$B41="Gabinete de pared"),MAX($J$5:$J40)+1,"") | K41: =IF($B41="Organizador vertical",COUNTIF($B$6:$B41,"Organizador vertical"),"") | L41: =IF($B41="Jack",COUNTIF($B$6:$B41,"Jack"),"") | M41: =IF(AND($C41<>"",N($F41)=0,$B41<>"Rack",$B41<>"Gabinete",$B41<>"Organizador vertical",$B41<>"Jack"),MAX($M$5:$M40)+1,"") | N41: 80 | O41: =IF(N41="","",ROUND(N41*3.412,0)) -> 273 | P41: 4.5
...

Sheet MUESTRA PISO
B2: ETIQUETADO Y ELEVACIÓN DE RACK — CUARTO DE TELECOMUNICACIONES
B3: =Proyecto!D6&""&IF(Proyecto!D7<>""," · Proyecto N.º "&Proyecto!D7,"")&IF(Proyecto!D8<>""," · "&Proyecto!D8,"")&IF(Proyecto!D11<>""," · Rev. "&Proyecto!D11,"")&IF(Proyecto!D9<>""," · Fecha: "&IF(ISNUMBER(Proyecto!D9),TEXT(Proyecto!D9,"dd/mm/yyyy"),Proyecto!D9),"")&IF(Proyecto!D10<>""," · Elaboró: "&Proyecto!D10,"") | AS3: =$E$6&"" -> 1A | AT3: =$J$6&"" -> Rack de piso 2 postes 45RU (machote) | AU3: =H43 -> 45 | AV3: =I43 -> 0 | AW3: =TEXT(J43,"0%") -> 100% | AX3: =COUNT($AE$13:$AE$42) -> 4 | AY3: =SUM($BF$13:$BF$28) -> 96 | AZ3: =$AQ$4 -> 0 | BA3: =IFERROR(TEXT($AZ$3/$AY$3,"0%"),"-") -> 0%
B4: MUESTRA PISO — machote de referencia. Esta pestaña NO se incluye en el Resumen. Para usarla: Ctrl + arrastrar hasta quedar entre INICIO_TR y FIN_TR y renombrar. | AQ4: =COUNTIF($CA$72:$CA$95,"?*")+COUNTIF($CB$72:$CB$95,"?*")+COUNTIF($CC$72:$CC$95,"?*")+COUNTIF($CD$72:$CD$95,"?*")+COUNTIF($CA$100:$CA$123,"?*")+COUNTIF($CB$100:$CB$123,"?*")+COUNTIF($CC$100:$CC$123,"?*")+COUNTIF($CD$100:$CD$123,"?*")+COUNTIF($CA$128:$CA$151,"?*")+COUNTIF($CB$128:$CB$151,"?*")+COUNTIF($CC$128:$CC$151,"?*")+COUNTIF($CD$128:$CD$151,"?*")+COUNTIF($CA$156:$CA$179,"?*")+COUNTIF($CB$156:$CB$179,"?*")+COUNTIF($CC$156:$CC$179,"?*")+COUNTIF($CD$156:$CD$179,"?*") -> 0
B5: DATOS DEL CUARTO | E5: / Room data | AR5: =IFERROR(IF(N(INDEX(Catalogo!$F$6:$F$125,MATCH($E$7,Catalogo!$C$6:$C$125,0)))=0,45,N(INDEX(Catalogo!$F$6:$F$125,MATCH($E$7,Catalogo!$C$6:$C$125,0)))),45) -> 45
B6: Código del cuarto | E6: 1A | H6: Descripción | J6: Rack de piso 2 postes 45RU (machote) | AR6: =SUM(H13:H42) -> 45 | BA6: =IF(OR(Catalogo!$C6="",Catalogo!$B6="Espacio libre",Catalogo!$B6="Espacio reservado"),0,COUNTIF($C$13:$C$42,Catalogo!$C6)+IF($E$7=Catalogo!$C6,N($K$7),0)+IF($E$8=Catalogo!$C6,N($N$8),0)+IF(Proyecto!$D$12=Catalogo!$C6,$AQ$4,0)+SUMIF($C$49:$C$58,Catalogo!$C6,$K$49:$K$58)) -> 1
B7: Rack / gabinete | E7: Rack 2 postes 45RU aluminio, canal 3", rosca #12-24 | J7: Cant. | K7: 1 | L7: Montaje | N7: =IFERROR(INDEX(Catalogo!$B$6:$B$125,MATCH($E$7,Catalogo!$C$6:$C$125,0))&" "&$AR$5&"RU","") -> Rack 45RU | BA7: =IF(OR(Catalogo!$C7="",Catalogo!$B7="Espacio libre",Catalogo!$B7="Espacio reservado"),0,COUNTIF($C$13:$C$42,Catalogo!$C7)+IF($E$7=Catalogo!$C7,N($K$7),0)+IF($E$8=Catalogo!$C7,N($N$8),0)+IF(Proyecto!$D$12=Catalogo!$C7,$AQ$4,0)+SUMIF($C$49:$C$58,Catalogo!$C7,$K$49:$K$58)) -> 0
B8: Organizador vertical | E8: Org. vertical 6" frontal/posterior (PatchRunner 2) | J8: Ubicación | K8: Ambos lados | M8: Cant. | N8: =IF($K$8="Ambos lados",2,IF(OR($K$8="Lado izquierdo",$K$8="Lado derecho"),1,0))*N($K$7) -> 2 | BA8: =IF(OR(Catalogo!$C8="",Catalogo!$B8="Espacio libre",Catalogo!$B8="Espacio reservado"),0,COUNTIF($C$13:$C$42,Catalogo!$C8)+IF($E$7=Catalogo!$C8,N($K$7),0)+IF($E$8=Catalogo!$C8,N($N$8),0)+IF(Proyecto!$D$12=Catalogo!$C8,$AQ$4,0)+SUMIF($C$49:$C$58,Catalogo!$C8,$K$49:$K$58)) -> 0
B9: Jack (Proyecto) | E9: =Proyecto!D12&"" -> Jack Cat 6A UTP azul (Mini-Com TX6A) | K9: Celdas amarillas = datos a llenar. En gabinete, use "Sin organizador" si el gabinete ya trae gestión vertical. | BA9: =IF(OR(Catalogo!$C9="",Catalogo!$B9="Espacio libre",Catalogo!$B9="Espacio reservado"),0,COUNTIF($C$13:$C$42,Catalogo!$C9)+IF($E$7=Catalogo!$C9,N($K$7),0)+IF($E$8=Catalogo!$C9,N($N$8),0)+IF(Proyecto!$D$12=Catalogo!$C9,$AQ$4,0)+SUMIF($C$49:$C$58,Catalogo!$C9,$K$49:$K$58)) -> 0
BA10: =IF(OR(Catalogo!$C10="",Catalogo!$B10="Espacio libre",Catalogo!$B10="Espacio reservado"),0,COUNTIF($C$13:$C$42,Catalogo!$C10)+IF($E$7=Catalogo!$C10,N($K$7),0)+IF($E$8=Catalogo!$C10,N($N$8),0)+IF(Proyecto!$D$12=Catalogo!$C10,$AQ$4,0)+SUMIF($C$49:$C$58,Catalogo!$C10,$K$49:$K$58)) -> 0
B11: EQUIPOS EN EL RACK | E11: (de arriba hacia abajo) | R11: VISTA DEL RACK | BA11: =IF(OR(Catalogo!$C11="",Catalogo!$B11="Espacio libre",Catalogo!$B11="Espacio reservado"),0,COUNTIF($C$13:$C$42,Catalogo!$C11)+IF($E$7=Catalogo!$C11,N($K$7),0)+IF($E$8=Catalogo!$C11,N($N$8),0)+IF(Proyecto!$D$12=Catalogo!$C11,$AQ$4,0)+SUMIF($C$49:$C$58,Catalogo!$C11,$K$49:$K$58)) -> 0
B12: # | C12: Equipo | F12: Número de parte | H12: RU | I12: Puertos | J12: RU sup. | K12: RU inf. | L12: Panel | M12: Tipo salida | N12: Salidas | O12: % llenado | P12: Utilización / notas | R12: Org. V. | S12: RU | T12: Equipo | W12: RU | X12: Org. V. | BA12: =IF(OR(Catalogo!$C12="",Catalogo!$B12="Espacio libre",Catalogo!$B12="Espacio reservado"),0,COUNTIF($C$13:$C$42,Catalogo!$C12)+IF($E$7=Catalogo!$C12,N($K$7),0)+IF($E$8=Catalogo!$C12,N($N$8),0)+IF(Proyecto!$D$12=Catalogo!$C12,$AQ$4,0)+SUMIF($C$49:$C$58,Catalogo!$C12,$K$49:$K$58)) -> 0 | BK12: =SUM($BG$13:$BG$28) -> 4
B13: 1 | C13: Bandeja de fibra 1RU FMD1 + adaptador LC FAP12WAQDLCZ | F13: =IF($C13="","",IFERROR(INDEX(Catalogo!$E$6:$E$125,MATCH($C13,Catalogo!$C$6:$C$125,0)),"")) -> FMD1 + FAP12WAQDLCZ | H13: =IF($C13="","",N(IFERROR(INDEX(Catalogo!$F$6:$F$125,MATCH($C13,Catalogo!$C$6:$C$125,0)),""))) -> 1 | I13: =IF($AD13<>"Patch panel cobre","",IFERROR(INDEX(Catalogo!$G$6:$G$125,MATCH($C13,Catalogo!$C$6:$C$125,0)),"")) | J13: =IF(OR($C13="",$H13=0),"",$AR$5-0) -> 45 | K13: =IF($J13="","",$J13-$H13+1) -> 45 | L13: =IF($AE13="","",$E$6&"-"&CHAR(65+INT(($AE13-1)/26))&CHAR(65+MOD($AE13-1,26))) | O13: =IF($AE13="","",IFERROR(INDEX($BS$13:$BS$28,$AE13)/INDEX($BF$13:$BF$28,$AE13),0)) | P13: Fibra óptica | R13: =IF(AND(OR($K$8="Ambos lados",$K$8="Lado izquierdo"),$E$8<>""),"ORGANIZADOR VERTICAL "&IFERROR(INDEX(Catalogo!$E$6:$E$125,MATCH($E$8,Catalogo!$C$6:$C$125,0)),""),"") -> ORGANIZADOR VERTICAL PR2VD06 | S13: 45 | T13: =IF($AM13=0,"",IF(INDEX($J$13:$J$42,$AM13)=45,INDEX($AH$13:$AH$42,$AM13),"")) -> Bandeja de fibra 1RU FMD1 + adaptador LC FAP12WAQDLCZ | W13: 45 | X13: =IF(AND(OR($K$8="Ambos lados",$K$8="Lado derecho"),$E$8<>""),"ORGANIZADOR VERTICAL "&IFERROR(INDEX(Catalogo!$E$6:$E$125,MATCH($E$8,Catalogo!$C$6:$C$125,0)),""),"") -> ORGANIZADOR VERTICAL PR2VD06 | AD13: =IF($C13="","",IFERROR(INDEX(Catalogo!$B$6:$B$125,MATCH($C13,Catalogo!$C$6:$C$125,0)),"")) -> Fibra | AE13: =IF($AD13="Patch panel cobre",COUNTIF($AD$13:$AD13,"Patch panel cobre"),"") | AH13: =IF($C13="","",IF($L13<>"","Patch panel "&$L13&" · "&$I13&" p"&IF($M13<>""," · "&$M13,""),$C13)) -> Bandeja de fibra 1RU FMD1 + adaptador LC FAP12WAQDLCZ | AM13: =IFERROR(MATCH(1,INDEX(($K$13:$K$42<=45)*($J$13:$J$42>=45),0),0),0) -> 1 | AN13: =IF(45>$AR$5,"Fuera",IF($AM13=0,"",INDEX($AD$13:$AD$42,$AM13))) -> Fibra | BA13: =IF(OR(Catalogo!$C13="",Catalogo!$B13="Espacio libre",Catalogo!$B13="Espacio reservado"),0,COUNTIF($C$13:$C$42,Catalogo!$C13)+IF($E$7=Catalogo!$C13,N($K$7),0)+IF($E$8=Catalogo!$C13,N($N$8),0)+IF(Proyecto!$D$12=Catalogo!$C13,$AQ$4,0)+SUMIF($C$49:$C$58,Catalogo!$C13,$K$49:$K$58)) -> 0 | BD13: =IFERROR(MATCH(1,$AE$13:$AE$42,0),"") -> 4 | BE13: =IF($BD13="","",INDEX($L$13:$L$42,$BD13)) -> 1A-AA | BF13: =IF($BD13="",0,N(INDEX($I$13:$I$42,$BD13))) -> 24 | BG13: =IF($BF13=0,0,ROUNDUP($BF13/24,0)) -> 1 | BH13: =0 -> 0 | BI13: =IF($BD13="","",INDEX($M$13:$M$42,$BD13)&"") | BJ13: {=IF($BD13="",0,IF(ISNUMBER(SEARCH(":",$BI13)),MIN($BF13,SUM(--MID(_xlfn.TEXTSPLIT($BI13,","),FIND(":",_xlfn.TEXTSPLIT($BI13,","))+1,9))),IF(INDEX($N$13:$N$42,$BD13)="",$BF13,MIN($BF13,N(INDEX($N$13:$N$42,$BD13))))))} -> 24 | BL13: =IF(1>$BK$12,"",MATCH(0,$BH$13:$BH$28,1)) -> 1 | BM13: =IF($BL13="",0,(0-INDEX($BH$13:$BH$28,$BL13))*24) -> 0 | BN13: =IF($BL13="","",INDEX($BE$13:$BE$28,$BL13)) -> 1A-AA | BO13: =IF($BL13="",0,INDEX($BF$13:$BF$28,$BL13)) -> 24 | BP13: =IF($BL13="","",INDEX($BI$13:$BI$28,$BL13)) | BQ13: =IF($BL13="",0,INDEX($BJ$13:$BJ$28,$BL13)) -> 24 | BR13: =COUNTIF($CA$72:$CA$95,"?*") -> 0 | BS13: =SUMIF($BL$13:$BL$28,1,$BR$13:$BR$28) -> 0 | CL13: =IF($C13="",0,N(IFERROR(INDEX(Catalogo!$N$6:$N$125,MATCH($C13,Catalogo!$C$6:$C$125,0)),0))) -> 0 | CM13: =IF($C13="",0,N(IFERROR(INDEX(Catalogo!$P$6:$P$125,MATCH($C13,Catalogo!$C$6:$C$125,0)),0))) -> 3 | CN13: =IF($C13="",0,N(IFERROR(INDEX(Catalogo!$Q$6:$Q$125,MATCH($C13,Catalogo!$C$6:$C$125,0)),0))) -> 0 | CO13: =IF($C13="",0,IF(OR($AD13="Espacio libre",$AD13="Espacio reservado"),0,IF(IFERROR(INDEX(Catalogo!$N$6:$N$125,MATCH($C13,Catalogo!$C$6:$C$125,0))="",TRUE),1,0))) -> 0
B14: 2 | C14: Bandeja de fibra 1RU FMD1 + adaptador LC FAP12WAQDLCZ | F14: =IF($C14="","",IFERROR(INDEX(Catalogo!$E$6:$E$125,MATCH($C14,Catalogo!$C$6:$C$125,0)),"")) -> FMD1 + FAP12WAQDLCZ | H14: =IF($C14="","",N(IFERROR(INDEX(Catalogo!$F$6:$F$125,MATCH($C14,Catalogo!$C$6:$C$125,0)),""))) -> 1 | I14: =IF($AD14<>"Patch panel cobre","",IFERROR(INDEX(Catalogo!$G$6:$G$125,MATCH($C14,Catalogo!$C$6:$C$125,0)),"")) | J14: =IF(OR($C14="",$H14=0),"",$AR$5-SUM($H$13:H13)) -> 44 | K14: =IF($J14="","",$J14-$H14+1) -> 44 | L14: =IF($AE14="","",$E$6&"-"&CHAR(65+INT(($AE14-1)/26))&CHAR(65+MOD($AE14-1,26))) | O14: =IF($AE14="","",IFERROR(INDEX($BS$13:$BS$28,$AE14)/INDEX($BF$13:$BF$28,$AE14),0)) | P14: Fibra óptica | S14: 44 | T14: =IF($AM14=0,"",IF(INDEX($J$13:$J$42,$AM14)=44,INDEX($AH$13:$AH$42,$AM14),"")) -> Bandeja de fibra 1RU FMD1 + adaptador LC FAP12WAQDLCZ | W14: 44 | AD14: =IF($C14="","",IFERROR(INDEX(Catalogo!$B$6:$B$125,MATCH($C14,Catalogo!$C$6:$C$125,0)),"")) -> Fibra | AE14: =IF($AD14="Patch panel cobre",COUNTIF($AD$13:$AD14,"Patch panel cobre"),"") | AH14: =IF($C14="","",IF($L14<>"","Patch panel "&$L14&" · "&$I14&" p"&IF($M14<>""," · "&$M14,""),$C14)) -> Bandeja de fibra 1RU FMD1 + adaptador LC FAP12WAQDLCZ | AM14: =IFERROR(MATCH(1,INDEX(($K$13:$K$42<=44)*($J$13:$J$42>=44),0),0),0) -> 2 | AN14: =IF(44>$AR$5,"Fuera",IF($AM14=0,"",INDEX($AD$13:$AD$42,$AM14))) -> Fibra | BA14: =IF(OR(Catalogo!$C14="",Catalogo!$B14="Espacio libre",Catalogo!$B14="Espacio reservado"),0,COUNTIF($C$13:$C$42,Catalogo!$C14)+IF($E$7=Catalogo!$C14,N($K$7),0)+IF($E$8=Catalogo!$C14,N($N$8),0)+IF(Proyecto!$D$12=Catalogo!$C14,$AQ$4,0)+SUMIF($C$49:$C$58,Catalogo!$C14,$K$49:$K$58)) -> 2 | BD14: =IFERROR(MATCH(2,$AE$13:$AE$42,0),"") -> 12 | BE14: =IF($BD14="","",INDEX($L$13:$L$42,$BD14)) -> 1A-AB | BF14: =IF($BD14="",0,N(INDEX($I$13:$I$42,$BD14))) -> 24 | BG14: =IF($BF14=0,0,ROUNDUP($BF14/24,0)) -> 1 | BH14: =SUM($BG$13:$BG13) -> 1 | BI14: =IF($BD14="","",INDEX($M$13:$M$42,$BD14)&"") | BJ14: {=IF($BD14="",0,IF(ISNUMBER(SEARCH(":",$BI14)),MIN($BF14,SUM(--MID(_xlfn.TEXTSPLIT($BI14,","),FIND(":",_xlfn.TEXTSPLIT($BI14,","))+1,9))),IF(INDEX($N$13:$N$42,$BD14)="",$BF14,MIN($BF14,N(INDEX($N$13:$N$42,$BD14))))))} -> 24 | BL14: =IF(2>$BK$12,"",MATCH(1,$BH$13:$BH$28,1)) -> 2 | BM14: =IF($BL14="",0,(1-INDEX($BH$13:$BH$28,$BL14))*24) -> 0 | BN14: =IF($BL14="","",INDEX($BE$13:$BE$28,$BL14)) -> 1A-AB | BO14: =IF($BL14="",0,INDEX($BF$13:$BF$28,$BL14)) -> 24 | BP14: =IF($BL14="","",INDEX($BI$13:$BI$28,$BL14)) | BQ14: =IF($BL14="",0,INDEX($BJ$13:$BJ$28,$BL14)) -> 24 | BR14: =COUNTIF($CB$72:$CB$95,"?*") -> 0 | BS14: =SUMIF($BL$13:$BL$28,2,$BR$13:$BR$28) -> 0 | CL14: =IF($C14="",0,N(IFERROR(INDEX(Catalogo!$N$6:$N$125,MATCH($C14,Catalogo!$C$6:$C$125,0)),0))) -> 0 | CM14: =IF($C14="",0,N(IFERROR(INDEX(Catalogo!$P$6:$P$125,MATCH($C14,Catalogo!$C$6:$C$125,0)),0))) -> 3 | CN14: =IF($C14="",0,N(IFERROR(INDEX(Catalogo!$Q$6:$Q$125,MATCH($C14,Catalogo!$C$6:$C$125,0)),0))) -> 0 | CO14: =IF($C14="",0,IF(OR($AD14="Espacio libre",$AD14="Espacio reservado"),0,IF(IFERROR(INDEX(Catalogo!$N$6:$N$125,MATCH($C14,Catalogo!$C$6:$C$125,0))="",TRUE),1,0))) -> 0
